Workbook

Sheet Financial Statements
A1: STATEMENT OF FINANCIAL POSITION
A2: FOR THE YEAR ENDING 2023, 2024 AND 2025
A4: Item | B4: 2023 | C4: 2024 | D4: 2025 | E4: FFC 2025 (Competitor)
A5: STATEMENT OF FINANCIAL POSITION
A6: NON-CURRENT ASSETS
A7: Property, Plant & Equipment | B7: 78440081 | C7: 83137431 | D7: 92391260 | E7: 132494031
A8: Intangible Assets | B8: 5184192 | C8: 5007551 | D8: 4779969 | E8: 2037672
A9: Long-term Investments | B9: 202134 | C9: 4268249 | D9: 4348915 | E9: 146225194
A10: Long-term Loans & Deposits | B10: 209806 | C10: 197921 | D10: 1534786 | E10: 4529993
A11: Long term deposits & prepayments | B11: 0 | C11: 0 | D11: 0 | E11: 146962
A12: Total Non-Current Assets | B12: =B7+B8+B9+B10 -> 84036213 | C12: =C7+C8+C9+C10 -> 92611152 | D12: =D7+D8+D9+D10 -> 103054930 | E12: =E7+E8+E9+E10+E11 -> 285433852
A13: CURRENT ASSETS
A14: Stores, Spares & Loose Tools | B14: 8729523 | C14: 8239527 | D14: 9151070 | E14: 18100523
A15: Stock-in-Trade | B15: 15355755 | C15: 26729059 | D15: 25691512 | E15: 45350440
A16: Trade Debts | B16: 2912495 | C16: 8253231 | D16: 16845896 | E16: 33901558
A17: Deposits and prepayments | B17: 0 | C17: 0 | D17: 0 | E17: 1515730
A18: Other Receivables | B18: 16056950 | C18: 11995667 | D18: 7834671 | E18: 8442339
A19: Loans, Advances & Deposits | B19: 3993197 | C19: 4594998 | D19: 3669419 | E19: 7554482
A20: Accured income | B20: 116629 | C20: 272080 | D20: 147159 | E20: 0
A21: Taxation - net | B21: 0 | C21: 9907395 | D21: 8689083 | E21: 0
A22: Short-term Investments | B22: 24062828 | C22: 3690852 | D22: 16012850 | E22: 199033962
A23: Cash & Bank Balances | B23: 4053684 | C23: 4308149 | D23: 8042747 | E23: 13965276
A24: Assets classified as held for sale | B24: 1525396 | C24: 0 | D24: 0 | E24: 0
A25: Total Current Assets | B25: =SUM(B14:B24) -> 76806457 | C25: =SUM(C14:C24) -> 77990958 | D25: =SUM(D14:D24) -> 96084407 | E25: =SUM(E14:E24) -> 327864310
A26: TOTAL ASSETS | B26: =B12+B25 -> 160842670 | C26: =C12+C25 -> 170602110 | D26: =D12+D25 -> 199139337 | E26: =E12+E25 -> 613298162
A27: EQUITY & LIABILITIES
A28: EQUITY
A29: Share Capital | B29: 13352993 | C29: 13352993 | D29: 13352993 | E29: 14231086
A30: Capital / Share Premium Reserves | B30: 3384904 | C30: 3384904 | D30: 3384904 | E30: 44630739
A31: General Reserve | E31: 8802360
A32: Remeasurement Reserve | B32: -74030 | C32: -69543 | D32: -38205 | E32: 0
A33: Surplus on remeausurement of:
A34: Investments to fair value net | E34: 7559791
A35: Share in Revaluation reserve of associates net | E35: 366742
A36: Unappropriated Profit | B36: 31238888 | C36: 30790190 | D36: 28047546 | E36: 184276548
A37: Non-Controlling Interest | B37: 0 | C37: 0 | D37: 0 | E37: 4937686
A38: Total Equity | B38: =SUM(B29:B37) -> 47902755 | C38: =SUM(C29:C37) -> 47458544 | D38: =SUM(D29:D37) -> 44747238 | E38: =SUM(E29:E37) -> 264804952
A39: NON-CURRENT LIABILITIES
A40: Long-term Borrowings | B40: 3267427 | C40: 18701703 | D40: 29445959 | E40: 50817992
A41: Government Grant | B41: 721334 | C41: 514355 | D41: 342634 | E41: 48222
...

Sheet Ratios
A1: ENGRO FERTILIZERS — FINANCIAL RATIOS (with FFC 2025 Competitor)
A2: Liquidity ratio
A3: Ratio | B3: Formula Used | C3: ENGRO 2023 | D3: ENGRO 2024 | E3: ENGRO 2025 | F3: FFC 2025
A4: A. LIQUIDITY RATIOS
A5: Current Ratio | B5: Current Assets ÷ Current Liabilities | C5: =IFERROR('Financial Statements'!B25/'Financial Statements'!B56,"N/A") -> 0.78124621 | D5: =IFERROR('Financial Statements'!C25/'Financial Statements'!C56,"N/A") -> 0.75714125 | E5: =IFERROR('Financial Statements'!D25/'Financial Statements'!D56,"N/A") -> 0.77116903 | F5: =IFERROR('Financial Statements'!E25/'Financial Statements'!E56,"N/A") -> 1.2712761
A6: Acid Test (Quick) Ratio | B6: (Current Assets − Inventory) ÷ Current Liabilities | C6: =IFERROR(('Financial Statements'!B25-'Financial Statements'!B15)/'Financial Statements'!B56,"N/A") -> 0.62505328 | D6: =IFERROR(('Financial Statements'!C25-'Financial Statements'!C15)/'Financial Statements'!C56,"N/A") -> 0.49765382 | E6: =IFERROR(('Financial Statements'!D25-'Financial Statements'!D15)/'Financial Statements'!D56,"N/A") -> 0.56497014 | F6: =IFERROR(('Financial Statements'!E25-'Financial Statements'!E15)/'Financial Statements'!E56,"N/A") -> 1.0954322
A8: B. FINANCIAL LEVERAGE / DEBT RATIOS
A9: Ratio | B9: Formula Used | C9: ENGRO 2023 | D9: ENGRO 2024 | E9: ENGRO 2025 | F9: FFC 2025
A10: Total Debt to Equity | B10: Total Liabilities ÷ Total Equity | C10: =IFERROR('Financial Statements'!B57/'Financial Statements'!B38,"N/A") -> 2.3576914 | D10: =IFERROR('Financial Statements'!C57/'Financial Statements'!C38,"N/A") -> 2.5947607 | E10: =IFERROR('Financial Statements'!D57/'Financial Statements'!D38,"N/A") -> 3.4509133 | F10: =IFERROR('Financial Statements'!E57/'Financial Statements'!E38,"N/A") -> 1.3160374
A11: Total Debt to Total Assets | B11: Total Liabilities ÷ Total Assets | C11: =IFERROR('Financial Statements'!B57/'Financial Statements'!B26,"N/A") -> 0.70217633 | D11: =IFERROR('Financial Statements'!C57/'Financial Statements'!C26,"N/A") -> 0.72181737 | E11: =IFERROR('Financial Statements'!D57/'Financial Statements'!D26,"N/A") -> 0.77543111 | F11: =IFERROR('Financial Statements'!E57/'Financial Statements'!E26,"N/A") -> 0.56822804
A12: Long-term Debt to Total Capital | B12: LT Borrowings ÷ (LT Borrowings + Total Equity) | C12: =IFERROR('Financial Statements'!B40/('Financial Statements'!B40+'Financial Statements'!B38),"N/A") -> 0.063854121 | D12: =IFERROR('Financial Statements'!C40/('Financial Statements'!C40+'Financial Statements'!C38),"N/A") -> 0.28267281 | E12: =IFERROR('Financial Statements'!D40/('Financial Statements'!D40+'Financial Statements'!D38),"N/A") -> 0.3968822 | F12: =IFERROR('Financial Statements'!E40/('Financial Statements'!E40+'Financial Statements'!E38),"N/A") -> 0.16100855
A14: C. COVERAGE RATIO
A15: Ratio | B15: Formula Used | C15: ENGRO 2023 | D15: ENGRO 2024 | E15: ENGRO 2025 | F15: FFC 2025
A16: Times Interest Earned (TIE / ICR) | B16: EBIT ÷ Finance Cost | C16: =IFERROR('Financial Statements'!B68/'Financial Statements'!B71,"N/A") -> 40.826862 | D16: =IFERROR('Financial Statements'!C68/'Financial Statements'!C71,"N/A") -> 12.030679 | E16: =IFERROR('Financial Statements'!D68/'Financial Statements'!D71,"N/A") -> 7.7165385 | F16: =IFERROR('Financial Statements'!E68/'Financial Statements'!E71,"N/A") -> 15.571446
A18: D. ACTIVITY / EFFICIENCY RATIOS(Days)
C19: ENGRO | F19: FFC
A20: Ratio | B20: Formula Used | C20: ENGRO 2023 | D20: ENGRO 2024 | E20: ENGRO 2025 | F20: FFC 2025
A21: Average Collection Period (ACP) | B21: (Trade Debts ÷ Net Sales) × 365 | C21: =IFERROR('Financial Statements'!B16/'Financial Statements'!B63*365,"N/A") -> 4.7520736 | D21: =IFERROR('Financial Statements'!C16/'Financial Statements'!C63*365,"N/A") -> 11.736349 | E21: =IFERROR('Financial Statements'!D16/'Financial Statements'!D63*365,"N/A") -> 25.929792 | F21: =IFERROR('Financial Statements'!E16/'Financial Statements'!E63*365,"N/A") -> 25.576427
A22: Payable Turnover in Days (PTO days) | B22: (Trade Payables ÷ COGS) × 365 | C22: =IFERROR('Financial Statements'!B47/'Financial Statements'!B64*365,"N/A") -> 178.62392 | D22: =IFERROR('Financial Statements'!C47/'Financial Statements'!C64*365,"N/A") -> 131.84673 | E22: =IFERROR('Financial Statements'!D47/'Financial Statements'!D64*365,"N/A") -> 145.70744 | F22: =IFERROR('Financial Statements'!E47/'Financial Statements'!E64*365,"N/A") -> 225.46217
A23: Inventory Turnover in Days (ITO days) | B23: (Stock-in-Trade ÷ COGS) × 365 | C23: =IFERROR('Financial Statements'!B15/'Financial Statements'!B64*365,"N/A") -> 37.018349 | D23: =IFERROR('Financial Statements'!C15/'Financial Statements'!C64*365,"N/A") -> 52.910023 | E23: =IFERROR('Financial Statements'!D15/'Financial Statements'!D64*365,"N/A") -> 56.978538 | F23: =IFERROR('Financial Statements'!E15/'Financial Statements'!E64*365,"N/A") -> 49.422297
A24: Operating Cycle | B24: ACP + ITO days | C24: =IFERROR(C21+C23,"N/A") -> 41.770422 | D24: =IFERROR(D21+D23,"N/A") -> 64.646372 | E24: =IFERROR(E21+E23,"N/A") -> 82.90833 | F24: =IFERROR(F21+F23,"N/A") -> 74.998724
A25: Cash Conversion Cycle | B25: Operating Cycle − PTO days | C25: =IFERROR(C24-C22,"N/A") -> -136.8535 | D25: =IFERROR(D24-D22,"N/A") -> -67.200362 | E25: =IFERROR(E24-E22,"N/A") -> -62.799111 | F25: =IFERROR(F24-F22,"N/A") -> -150.46345
A26: D. ACTIVITY / EFFICIENCY RATIOS
C27: ENGRO | F27: FFC
A28: Ratio | B28: Formula Used | C28: 2023 | D28: 2024 | E28: 2025 | F28: 2025
A29: Receivable Turnover | B29: Net Sales ÷ Trade Debts | C29: =IFERROR('Financial Statements'!B63/'Financial Statements'!B16,"N/A") -> 76.808575 | D29: =IFERROR('Financial Statements'!C63/'Financial Statements'!C16,"N/A") -> 31.099961 | E29: =IFERROR('Financial Statements'!D63/'Financial Statements'!D16,"N/A") -> 14.076472 | F29: =IFERROR('Financial Statements'!E63/'Financial Statements'!E16,"N/A") -> 14.270954
A30: Payable Turnover (PTO) | B30: COGS ÷ Trade Payables | C30: =IFERROR('Financial Statements'!B64/'Financial Statements'!B47,"N/A") -> 2.0433993 | D30: =IFERROR('Financial Statements'!C64/'Financial Statements'!C47,"N/A") -> 2.7683659 | E30: =IFERROR('Financial Statements'!D64/'Financial Statements'!D47,"N/A") -> 2.5050196 | F30: =IFERROR('Financial Statements'!E64/'Financial Statements'!E47,"N/A") -> 1.6188968
A31: Inventory Turnover (ITO) | B31: COGS ÷ Stock-in-Trade | C31: =IFERROR('Financial Statements'!B64/'Financial Statements'!B15,"N/A") -> 9.8599752 | D31: =IFERROR('Financial Statements'!C64/'Financial Statements'!C15,"N/A") -> 6.8985039 | E31: =IFERROR('Financial Statements'!D64/'Financial Statements'!D15,"N/A") -> 6.4059208 | F31: =IFERROR('Financial Statements'!E64/'Financial Statements'!E15,"N/A") -> 7.3853306
A32: Total Asset Turnover | B32: Net Sales ÷ Total Assets | C32: =IFERROR('Financial Statements'!B63/'Financial Statements'!B26,"N/A") -> 1.3908286 | D32: =IFERROR('Financial Statements'!C63/'Financial Statements'!C26,"N/A") -> 1.5045251 | E32: =IFERROR('Financial Statements'!D63/'Financial Statements'!D26,"N/A") -> 1.1907782 | F32: =IFERROR('Financial Statements'!E63/'Financial Statements'!E26,"N/A") -> 0.78886191
A34: E. PROFITABILITY RATIOS
A35: Ratio | B35: Formula Used | C35: ENGRO 2023 | D35: ENGRO 2024 | E35: ENGRO 2025 | F35: FFC 2025
A36: Gross Profit (GP) Margin | B36: Gross Profit ÷ Net Sales | C36: =IFERROR('Financial Statements'!B65/'Financial Statements'!B63,"N/A") -> 0.32318169 | D36: =IFERROR('Financial Statements'!C65/'Financial Statements'!C63,"N/A") -> 0.28161917 | E36: =IFERROR('Financial Statements'!D65/'Financial Statements'!D63,"N/A") -> 0.30596194 | F36: =IFERROR('Financial Statements'!E65/'Financial Statements'!E63,"N/A") -> 0.30772477
A37: Net Profit (NP) Margin | B37: Net Profit ÷ Net Sales | C37: =IFERROR('Financial Statements'!B76/'Financial Statements'!B63,"N/A") -> 0.11707896 | D37: =IFERROR('Financial Statements'!C76/'Financial Statements'!C63,"N/A") -> 0.11010118 | E37: =IFERROR('Financial Statements'!D76/'Financial Statements'!D63,"N/A") -> 0.09542432 | F37: =IFERROR('Financial Statements'!E76/'Financial Statements'!E63,"N/A") -> 0.17582704
A38: Return on Investment / ROA | B38: Net Profit ÷ Total Assets | C38: =IFERROR('Financial Statements'!B76/'Financial Statements'!B26,"N/A") -> 0.16283678 | D38: =IFERROR('Financial Statements'!C76/'Financial Statements'!C26,"N/A") -> 0.16564999 | E38: =IFERROR('Financial Statements'!D76/'Financial Statements'!D26,"N/A") -> 0.1136292 | F38: =IFERROR('Financial Statements'!E76/'Financial Statements'!E26,"N/A") -> 0.13870325
A39: Return on Equity (ROE) | B39: Net Profit ÷ Total Equity | C39: =IFERROR('Financial Statements'!B76/'Financial Statements'!B38,"N/A") -> 0.54675565 | D39: =IFERROR('Financial Statements'!C76/'Financial Statements'!C38,"N/A") -> 0.59547208 | E39: =IFERROR('Financial Statements'!D76/'Financial Statements'!D38,"N/A") -> 0.50568583 | F39: =IFERROR('Financial Statements'!E76/'Financial Statements'!E38,"N/A") -> 0.32124192

Sheet Vertical + Horizontal
A1: ENGRO FERTILIZERS LIMITED — VERTICAL (COMMON-SIZE) & HORIZONTAL (INDEX) ANALYSIS
A2: VERTICAL / COMMON-SIZE ANALYSIS (Absolute Values & % of Base) | I2: HORIZONTAL / INDEX ANALYSIS (Base Year = 2023)
A3: BALANCE SHEET | I3: BALANCE SHEET
A4: Item | B4: 2023 (Rs '000) | C4: 2023 % | D4: 2024 (Rs '000) | E4: 2024 % | F4: 2025 (Rs '000) | G4: 2025 % | I4: Item | J4: 2023 (Base=100%) | K4: 2024 vs 2023 | L4: 2025 vs 2023 | M4: FFC 2025 (Ref.)
A5: NON-CURRENT ASSETS | I5: NON-CURRENT ASSETS
A6: Property, Plant & Equipment | B6: ='Financial Statements'!B7 -> 78440081 | C6: =IFERROR('Financial Statements'!B7/'Financial Statements'!B26,0) -> 0.48768204 | D6: ='Financial Statements'!C7 -> 83137431 | E6: =IFERROR('Financial Statements'!C7/'Financial Statements'!C26,0) -> 0.48731772 | F6: ='Financial Statements'!D7 -> 92391260 | G6: =IFERROR('Financial Statements'!D7/'Financial Statements'!D26,0) -> 0.46395284 | I6: Property, Plant & Equipment | J6: =IFERROR('Financial Statements'!B7/'Financial Statements'!B7,0) -> 1 | K6: =IFERROR('Financial Statements'!C7/'Financial Statements'!B7,0) -> 1.0598846 | L6: =IFERROR('Financial Statements'!D7/'Financial Statements'!B7,0) -> 1.1778578 | M6: =IFERROR('Financial Statements'!E7/'Financial Statements'!B7,0) -> 1.6891113
A7: Intangible Assets | B7: ='Financial Statements'!B8 -> 5184192 | C7: =IFERROR('Financial Statements'!B8/'Financial Statements'!B26,0) -> 0.032231447 | D7: ='Financial Statements'!C8 -> 5007551 | E7: =IFERROR('Financial Statements'!C8/'Financial Statements'!C26,0) -> 0.029352222 | F7: ='Financial Statements'!D8 -> 4779969 | G7: =IFERROR('Financial Statements'!D8/'Financial Statements'!D26,0) -> 0.024003138 | I7: Intangible Assets | J7: =IFERROR('Financial Statements'!B8/'Financial Statements'!B8,0) -> 1 | K7: =IFERROR('Financial Statements'!C8/'Financial Statements'!B8,0) -> 0.96592699 | L7: =IFERROR('Financial Statements'!D8/'Financial Statements'!B8,0) -> 0.92202777 | M7: =IFERROR('Financial Statements'!E8/'Financial Statements'!B8,0) -> 0.39305489
A8: Long-term Investments | B8: ='Financial Statements'!B9 -> 202134 | C8: =IFERROR('Financial Statements'!B9/'Financial Statements'!B26,0) -> 0.0012567188 | D8: ='Financial Statements'!C9 -> 4268249 | E8: =IFERROR('Financial Statements'!C9/'Financial Statements'!C26,0) -> 0.025018735 | F8: ='Financial Statements'!D9 -> 4348915 | G8: =IFERROR('Financial Statements'!D9/'Financial Statements'!D26,0) -> 0.021838553 | I8: Long-term Investments | J8: =IFERROR('Financial Statements'!B9/'Financial Statements'!B9,0) -> 1 | K8: =IFERROR('Financial Statements'!C9/'Financial Statements'!B9,0) -> 21.115938 | L8: =IFERROR('Financial Statements'!D9/'Financial Statements'!B9,0) -> 21.51501 | M8: =IFERROR('Financial Statements'!E9/'Financial Statements'!B9,0) -> 723.40722
A9: Long-term Loans & Deposits | B9: ='Financial Statements'!B10 -> 209806 | C9: =IFERROR('Financial Statements'!B10/'Financial Statements'!B26,0) -> 0.0013044175 | D9: ='Financial Statements'!C10 -> 197921 | E9: =IFERROR('Financial Statements'!C10/'Financial Statements'!C26,0) -> 0.0011601322 | F9: ='Financial Statements'!D10 -> 1534786 | G9: =IFERROR('Financial Statements'!D10/'Financial Statements'!D26,0) -> 0.0077070961 | I9: Long-term Loans & Deposits | J9: =IFERROR('Financial Statements'!B10/'Financial Statements'!B10,0) -> 1 | K9: =IFERROR('Financial Statements'!C10/'Financial Statements'!B10,0) -> 0.94335243 | L9: =IFERROR('Financial Statements'!D10/'Financial Statements'!B10,0) -> 7.3152627 | M9: =IFERROR('Financial Statements'!E10/'Financial Statements'!B10,0) -> 21.591342
A10: Long-term Deposits & Prepayments | B10: ='Financial Statements'!B11 -> 0 | C10: =IFERROR('Financial Statements'!B11/'Financial Statements'!B26,0) -> 0 | D10: ='Financial Statements'!C11 -> 0 | E10: =IFERROR('Financial Statements'!C11/'Financial Statements'!C26,0) -> 0 | F10: ='Financial Statements'!D11 -> 0 | G10: =IFERROR('Financial Statements'!D11/'Financial Statements'!D26,0) -> 0 | I10: Long-term Deposits & Prepayments | J10: =IFERROR('Financial Statements'!B11/'Financial Statements'!B11,0) -> 0 | K10: =IFERROR('Financial Statements'!C11/'Financial Statements'!B11,0) -> 0 | L10: =IFERROR('Financial Statements'!D11/'Financial Statements'!B11,0) -> 0 | M10: =IFERROR('Financial Statements'!E11/'Financial Statements'!B11,0) -> 0
A11: Total Non-Current Assets | B11: ='Financial Statements'!B12 -> 84036213 | C11: =IFERROR('Financial Statements'!B12/'Financial Statements'!B26,0) -> 0.52247462 | D11: ='Financial Statements'!C12 -> 92611152 | E11: =IFERROR('Financial Statements'!C12/'Financial Statements'!C26,0) -> 0.54284881 | F11: ='Financial Statements'!D12 -> 103054930 | G11: =IFERROR('Financial Statements'!D12/'Financial Statements'!D26,0) -> 0.51750162 | I11: Total Non-Current Assets | J11: =IFERROR('Financial Statements'!B12/'Financial Statements'!B12,0) -> 1 | K11: =IFERROR('Financial Statements'!C12/'Financial Statements'!B12,0) -> 1.1020386 | L11: =IFERROR('Financial Statements'!D12/'Financial Statements'!B12,0) -> 1.2263157 | M11: =IFERROR('Financial Statements'!E12/'Financial Statements'!B12,0) -> 3.3965578
A12: CURRENT ASSETS | I12: CURRENT ASSETS
A13: Stores, Spares & Loose Tools | B13: ='Financial Statements'!B14 -> 8729523 | C13: =IFERROR('Financial Statements'!B14/'Financial Statements'!B26,0) -> 0.054273676 | D13: ='Financial Statements'!C14 -> 8239527 | E13: =IFERROR('Financial Statements'!C14/'Financial Statements'!C26,0) -> 0.048296747 | F13: ='Financial Statements'!D14 -> 9151070 | G13: =IFERROR('Financial Statements'!D14/'Financial Statements'!D26,0) -> 0.045953101 | I13: Stores, Spares & Loose Tools | J13: =IFERROR('Financial Statements'!B14/'Financial Statements'!B14,0) -> 1 | K13: =IFERROR('Financial Statements'!C14/'Financial Statements'!B14,0) -> 0.9438691 | L13: =IFERROR('Financial Statements'!D14/'Financial Statements'!B14,0) -> 1.0482898 | M13: =IFERROR('Financial Statements'!E14/'Financial Statements'!B14,0) -> 2.0734836
A14: Stock-in-Trade | B14: ='Financial Statements'!B15 -> 15355755 | C14: =IFERROR('Financial Statements'!B15/'Financial Statements'!B26,0) -> 0.095470655 | D14: ='Financial Statements'!C15 -> 26729059 | E14: =IFERROR('Financial Statements'!C15/'Financial Statements'!C26,0) -> 0.15667484 | F14: ='Financial Statements'!D15 -> 25691512 | G14: =IFERROR('Financial Statements'!D15/'Financial Statements'!D26,0) -> 0.12901274 | I14: Stock-in-Trade | J14: =IFERROR('Financial Statements'!B15/'Financial Statements'!B15,0) -> 1 | K14: =IFERROR('Financial Statements'!C15/'Financial Statements'!B15,0) -> 1.7406542 | L14: =IFERROR('Financial Statements'!D15/'Financial Statements'!B15,0) -> 1.6730869 | M14: =IFERROR('Financial Statements'!E15/'Financial Statements'!B15,0) -> 2.9533188
A15: Trade Debts | B15: ='Financial Statements'!B16 -> 2912495 | C15: =IFERROR('Financial Statements'!B16/'Financial Statements'!B26,0) -> 0.018107726 | D15: ='Financial Statements'!C16 -> 8253231 | E15: =IFERROR('Financial Statements'!C16/'Financial Statements'!C26,0) -> 0.048377075 | F15: ='Financial Statements'!D16 -> 16845896 | G15: =IFERROR('Financial Statements'!D16/'Financial Statements'!D26,0) -> 0.084593513 | I15: Trade Debts | J15: =IFERROR('Financial Statements'!B16/'Financial Statements'!B16,0) -> 1 | K15: =IFERROR('Financial Statements'!C16/'Financial Statements'!B16,0) -> 2.8337322 | L15: =IFERROR('Financial Statements'!D16/'Financial Statements'!B16,0) -> 5.7840086 | M15: =IFERROR('Financial Statements'!E16/'Financial Statements'!B16,0) -> 11.64004
A16: Deposits & Prepayments | B16: ='Financial Statements'!B17 -> 0 | C16: =IFERROR('Financial Statements'!B17/'Financial Statements'!B26,0) -> 0 | D16: ='Financial Statements'!C17 -> 0 | E16: =IFERROR('Financial Statements'!C17/'Financial Statements'!C26,0) -> 0 | F16: ='Financial Statements'!D17 -> 0 | G16: =IFERROR('Financial Statements'!D17/'Financial Statements'!D26,0) -> 0 | I16: Deposits & Prepayments | J16: =IFERROR('Financial Statements'!B17/'Financial Statements'!B17,0) -> 0 | K16: =IFERROR('Financial Statements'!C17/'Financial Statements'!B17,0) -> 0 | L16: =IFERROR('Financial Statements'!D17/'Financial Statements'!B17,0) -> 0 | M16: =IFERROR('Financial Statements'!E17/'Financial Statements'!B17,0) -> 0
A17: Other Receivables | B17: ='Financial Statements'!B18 -> 16056950 | C17: =IFERROR('Financial Statements'!B18/'Financial Statements'!B26,0) -> 0.099830163 | D17: ='Financial Statements'!C18 -> 11995667 | E17: =IFERROR('Financial Statements'!C18/'Financial Statements'!C26,0) -> 0.070313708 | F17: ='Financial Statements'!D18 -> 7834671 | G17: =IFERROR('Financial Statements'!D18/'Financial Statements'!D26,0) -> 0.039342659 | I17: Other Receivables | J17: =IFERROR('Financial Statements'!B18/'Financial Statements'!B18,0) -> 1 | K17: =IFERROR('Financial Statements'!C18/'Financial Statements'!B18,0) -> 0.74707008 | L17: =IFERROR('Financial Statements'!D18/'Financial Statements'!B18,0) -> 0.48793021 | M17: =IFERROR('Financial Statements'!E18/'Financial Statements'!B18,0) -> 0.52577476
A18: Loans, Advances & Deposits | B18: ='Financial Statements'!B19 -> 3993197 | C18: =IFERROR('Financial Statements'!B19/'Financial Statements'!B26,0) -> 0.024826727 | D18: ='Financial Statements'!C19 -> 4594998 | E18: =IFERROR('Financial Statements'!C19/'Financial Statements'!C26,0) -> 0.026934005 | F18: ='Financial Statements'!D19 -> 3669419 | G18: =IFERROR('Financial Statements'!D19/'Financial Statements'!D26,0) -> 0.01842639 | I18: Loans, Advances & Deposits | J18: =IFERROR('Financial Statements'!B19/'Financial Statements'!B19,0) -> 1 | K18: =IFERROR('Financial Statements'!C19/'Financial Statements'!B19,0) -> 1.1507066 | L18: =IFERROR('Financial Statements'!D19/'Financial Statements'!B19,0) -> 0.9189176 | M18: =IFERROR('Financial Statements'!E19/'Financial Statements'!B19,0) -> 1.891838
A19: Accrued Income | B19: ='Financial Statements'!B20 -> 116629 | C19: =IFERROR('Financial Statements'!B20/'Financial Statements'!B26,0) -> 0.00072511231 | D19: ='Financial Statements'!C20 -> 272080 | E19: =IFERROR('Financial Statements'!C20/'Financial Statements'!C26,0) -> 0.001594822 | F19: ='Financial Statements'!D20 -> 147159 | G19: =IFERROR('Financial Statements'!D20/'Financial Statements'!D26,0) -> 0.00073897504 | I19: Accrued Income | J19: =IFERROR('Financial Statements'!B20/'Financial Statements'!B20,0) -> 1 | K19: =IFERROR('Financial Statements'!C20/'Financial Statements'!B20,0) -> 2.3328675 | L19: =IFERROR('Financial Statements'!D20/'Financial Statements'!B20,0) -> 1.2617702 | M19: =IFERROR('Financial Statements'!E20/'Financial Statements'!B20,0) -> 0
A20: Taxation - net | B20: ='Financial Statements'!B21 -> 0 | C20: =IFERROR('Financial Statements'!B21/'Financial Statements'!B26,0) -> 0 | D20: ='Financial Statements'!C21 -> 9907395 | E20: =IFERROR('Financial Statements'!C21/'Financial Statements'!C26,0) -> 0.058073109 | F20: ='Financial Statements'!D21 -> 8689083 | G20: =IFERROR('Financial Statements'!D21/'Financial Statements'!D26,0) -> 0.043633182 | I20: Taxation - net | J20: =IFERROR('Financial Statements'!B21/'Financial Statements'!B21,0) -> 0 | K20: =IFERROR('Financial Statements'!C21/'Financial Statements'!B21,0) -> 0 | L20: =IFERROR('Financial Statements'!D21/'Financial Statements'!B21,0) -> 0 | M20: =IFERROR('Financial Statements'!E21/'Financial Statements'!B21,0) -> 0
A21: Short-term Investments | B21: ='Financial Statements'!B22 -> 24062828 | C21: =IFERROR('Financial Statements'!B22/'Financial Statements'!B26,0) -> 0.14960475 | D21: ='Financial Statements'!C22 -> 3690852 | E21: =IFERROR('Financial Statements'!C22/'Financial Statements'!C26,0) -> 0.021634269 | F21: ='Financial Statements'!D22 -> 16012850 | G21: =IFERROR('Financial Statements'!D22/'Financial Statements'!D26,0) -> 0.080410281 | I21: Short-term Investments | J21: =IFERROR('Financial Statements'!B22/'Financial Statements'!B22,0) -> 1 | K21: =IFERROR('Financial Statements'!C22/'Financial Statements'!B22,0) -> 0.15338397 | L21: =IFERROR('Financial Statements'!D22/'Financial Statements'!B22,0) -> 0.66546002 | M21: =IFERROR('Financial Statements'!E22/'Financial Statements'!B22,0) -> 8.2714285
A22: Cash & Bank Balances | B22: ='Financial Statements'!B23 -> 4053684 | C22: =IFERROR('Financial Statements'!B23/'Financial Statements'!B26,0) -> 0.02520279 | D22: ='Financial Statements'!C23 -> 4308149 | E22: =IFERROR('Financial Statements'!C23/'Financial Statements'!C26,0) -> 0.025252613 | F22: ='Financial Statements'!D23 -> 8042747 | G22: =IFERROR('Financial Statements'!D23/'Financial Statements'!D26,0) -> 0.040387535 | I22: Cash & Bank Balances | J22: =IFERROR('Financial Statements'!B23/'Financial Statements'!B23,0) -> 1 | K22: =IFERROR('Financial Statements'!C23/'Financial Statements'!B23,0) -> 1.0627738 | L22: =IFERROR('Financial Statements'!D23/'Financial Statements'!B23,0) -> 1.9840587 | M22: =IFERROR('Financial Statements'!E23/'Financial Statements'!B23,0) -> 3.4450825
A23: Assets Held for Sale | B23: ='Financial Statements'!B24 -> 1525396 | C23: =IFERROR('Financial Statements'!B24/'Financial Statements'!B26,0) -> 0.0094837769 | D23: ='Financial Statements'!C24 -> 0 | E23: =IFERROR('Financial Statements'!C24/'Financial Statements'!C26,0) -> 0 | F23: ='Financial Statements'!D24 -> 0 | G23: =IFERROR('Financial Statements'!D24/'Financial Statements'!D26,0) -> 0 | I23: Assets Held for Sale | J23: =IFERROR('Financial Statements'!B24/'Financial Statements'!B24,0) -> 1 | K23: =IFERROR('Financial Statements'!C24/'Financial Statements'!B24,0) -> 0 | L23: =IFERROR('Financial Statements'!D24/'Financial Statements'!B24,0) -> 0 | M23: =IFERROR('Financial Statements'!E24/'Financial Statements'!B24,0) -> 0
A24: Total Current Assets | B24: ='Financial Statements'!B25 -> 76806457 | C24: =IFERROR('Financial Statements'!B25/'Financial Statements'!B26,0) -> 0.47752538 | D24: ='Financial Statements'!C25 -> 77990958 | E24: =IFERROR('Financial Statements'!C25/'Financial Statements'!C26,0) -> 0.45715119 | F24: ='Financial Statements'!D25 -> 96084407 | G24: =IFERROR('Financial Statements'!D25/'Financial Statements'!D26,0) -> 0.48249838 | I24: Total Current Assets | J24: =IFERROR('Financial Statements'!B25/'Financial Statements'!B25,0) -> 1 | K24: =IFERROR('Financial Statements'!C25/'Financial Statements'!B25,0) -> 1.0154219 | L24: =IFERROR('Financial Statements'!D25/'Financial Statements'!B25,0) -> 1.2509939 | M24: =IFERROR('Financial Statements'!E25/'Financial Statements'!B25,0) -> 4.2687076
A25: TOTAL ASSETS (= 100%) | B25: ='Financial Statements'!B26 -> 160842670 | C25: =IFERROR('Financial Statements'!B26/'Financial Statements'!B26,0) -> 1 | D25: ='Financial Statements'!C26 -> 170602110 | E25: =IFERROR('Financial Statements'!C26/'Financial Statements'!C26,0) -> 1 | F25: ='Financial Statements'!D26 -> 199139337 | G25: =IFERROR('Financial Statements'!D26/'Financial Statements'!D26,0) -> 1 | I25: TOTAL ASSETS (= 100%) | J25: =IFERROR('Financial Statements'!B26/'Financial Statements'!B26,0) -> 1 | K25: =IFERROR('Financial Statements'!C26/'Financial Statements'!B26,0) -> 1.0606769 | L25: =IFERROR('Financial Statements'!D26/'Financial Statements'!B26,0) -> 1.2381002 | M25: =IFERROR('Financial Statements'!E26/'Financial Statements'!B26,0) -> 3.8130315
A26: EQUITY & LIABILITIES | I26: EQUITY & LIABILITIES
A27: EQUITY | I27: EQUITY
A28: Share Capital | B28: ='Financial Statements'!B29 -> 13352993 | C28: =IFERROR('Financial Statements'!B29/'Financial Statements'!B26,0) -> 0.083018971 | D28: ='Financial Statements'!C29 -> 13352993 | E28: =IFERROR('Financial Statements'!C29/'Financial Statements'!C26,0) -> 0.0782698 | F28: ='Financial Statements'!D29 -> 13352993 | G28: =IFERROR('Financial Statements'!D29/'Financial Statements'!D26,0) -> 0.067053517 | I28: Share Capital | J28: =IFERROR('Financial Statements'!B29/'Financial Statements'!B29,0) -> 1 | K28: =IFERROR('Financial Statements'!C29/'Financial Statements'!B29,0) -> 1 | L28: =IFERROR('Financial Statements'!D29/'Financial Statements'!B29,0) -> 1 | M28: =IFERROR('Financial Statements'!E29/'Financial Statements'!B29,0) -> 1.06576
A29: Capital / Share Premium Reserves | B29: ='Financial Statements'!B30 -> 3384904 | C29: =IFERROR('Financial Statements'!B30/'Financial Statements'!B26,0) -> 0.021044814 | D29: ='Financial Statements'!C30 -> 3384904 | E29: =IFERROR('Financial Statements'!C30/'Financial Statements'!C26,0) -> 0.019840927 | F29: ='Financial Statements'!D30 -> 3384904 | G29: =IFERROR('Financial Statements'!D30/'Financial Statements'!D26,0) -> 0.016997666 | I29: Capital / Share Premium Reserves | J29: =IFERROR('Financial Statements'!B30/'Financial Statements'!B30,0) -> 1 | K29: =IFERROR('Financial Statements'!C30/'Financial Statements'!B30,0) -> 1 | L29: =IFERROR('Financial Statements'!D30/'Financial Statements'!B30,0) -> 1 | M29: =IFERROR('Financial Statements'!E30/'Financial Statements'!B30,0) -> 13.18523
A30: General Reserve | B30: ='Financial Statements'!B31 -> 0 | C30: =IFERROR('Financial Statements'!B31/'Financial Statements'!B26,0) -> 0 | D30: ='Financial Statements'!C31 -> 0 | E30: =IFERROR('Financial Statements'!C31/'Financial Statements'!C26,0) -> 0 | F30: ='Financial Statements'!D31 -> 0 | G30: =IFERROR('Financial Statements'!D31/'Financial Statements'!D26,0) -> 0 | I30: General Reserve | J30: =IFERROR('Financial Statements'!B31/'Financial Statements'!B31,0) -> 0 | K30: =IFERROR('Financial Statements'!C31/'Financial Statements'!B31,0) -> 0 | L30: =IFERROR('Financial Statements'!D31/'Financial Statements'!B31,0) -> 0 | M30: =IFERROR('Financial Statements'!E31/'Financial Statements'!B31,0) -> 0
A31: Remeasurement Reserve | B31: ='Financial Statements'!B32 -> -74030 | C31: =IFERROR('Financial Statements'!B32/'Financial Statements'!B26,0) -> -0.00046026344 | D31: ='Financial Statements'!C32 -> -69543 | E31: =IFERROR('Financial Statements'!C32/'Financial Statements'!C26,0) -> -0.00040763271 | F31: ='Financial Statements'!D32 -> -38205 | G31: =IFERROR('Financial Statements'!D32/'Financial Statements'!D26,0) -> -0.00019185059 | I31: Remeasurement Reserve | J31: =IFERROR('Financial Statements'!B32/'Financial Statements'!B32,0) -> 1 | K31: =IFERROR('Financial Statements'!C32/'Financial Statements'!B32,0) -> 0.93938944 | L31: =IFERROR('Financial Statements'!D32/'Financial Statements'!B32,0) -> 0.51607456 | M31: =IFERROR('Financial Statements'!E32/'Financial Statements'!B32,0) -> 0
A32: Surplus - Investments to Fair Value | B32: ='Financial Statements'!B34 -> 0 | C32: =IFERROR('Financial Statements'!B34/'Financial Statements'!B26,0) -> 0 | D32: ='Financial Statements'!C34 -> 0 | E32: =IFERROR('Financial Statements'!C34/'Financial Statements'!C26,0) -> 0 | F32: ='Financial Statements'!D34 -> 0 | G32: =IFERROR('Financial Statements'!D34/'Financial Statements'!D26,0) -> 0 | I32: Surplus - Investments to Fair Value | J32: =IFERROR('Financial Statements'!B34/'Financial Statements'!B34,0) -> 0 | K32: =IFERROR('Financial Statements'!C34/'Financial Statements'!B34,0) -> 0 | L32: =IFERROR('Financial Statements'!D34/'Financial Statements'!B34,0) -> 0 | M32: =IFERROR('Financial Statements'!E34/'Financial Statements'!B34,0) -> 0
A33: Share in Revaluation Res. of Assoc. | B33: ='Financial Statements'!B35 -> 0 | C33: =IFERROR('Financial Statements'!B35/'Financial Statements'!B26,0) -> 0 | D33: ='Financial Statements'!C35 -> 0 | E33: =IFERROR('Financial Statements'!C35/'Financial Statements'!C26,0) -> 0 | F33: ='Financial Statements'!D35 -> 0 | G33: =IFERROR('Financial Statements'!D35/'Financial Statements'!D26,0) -> 0 | I33: Share in Revaluation Res. of Assoc. | J33: =IFERROR('Financial Statements'!B35/'Financial Statements'!B35,0) -> 0 | K33: =IFERROR('Financial Statements'!C35/'Financial Statements'!B35,0) -> 0 | L33: =IFERROR('Financial Statements'!D35/'Financial Statements'!B35,0) -> 0 | M33: =IFERROR('Financial Statements'!E35/'Financial Statements'!B35,0) -> 0
A34: Unappropriated Profit | B34: ='Financial Statements'!B36 -> 31238888 | C34: =IFERROR('Financial Statements'!B36/'Financial Statements'!B26,0) -> 0.19422015 | D34: ='Financial Statements'!C36 -> 30790190 | E34: =IFERROR('Financial Statements'!C36/'Financial Statements'!C26,0) -> 0.18047954 | F34: ='Financial Statements'!D36 -> 28047546 | G34: =IFERROR('Financial Statements'!D36/'Financial Statements'!D26,0) -> 0.14084383 | I34: Unappropriated Profit | J34: =IFERROR('Financial Statements'!B36/'Financial Statements'!B36,0) -> 1 | K34: =IFERROR('Financial Statements'!C36/'Financial Statements'!B36,0) -> 0.98563656 | L34: =IFERROR('Financial Statements'!D36/'Financial Statements'!B36,0) -> 0.89784073 | M34: =IFERROR('Financial Statements'!E36/'Financial Statements'!B36,0) -> 5.8989471
A35: Non-Controlling Interest | B35: ='Financial Statements'!B37 -> 0 | C35: =IFERROR('Financial Statements'!B37/'Financial Statements'!B26,0) -> 0 | D35: ='Financial Statements'!C37 -> 0 | E35: =IFERROR('Financial Statements'!C37/'Financial Statements'!C26,0) -> 0 | F35: ='Financial Statements'!D37 -> 0 | G35: =IFERROR('Financial Statements'!D37/'Financial Statements'!D26,0) -> 0 | I35: Non-Controlling Interest | J35: =IFERROR('Financial Statements'!B37/'Financial Statements'!B37,0) -> 0 | K35: =IFERROR('Financial Statements'!C37/'Financial Statements'!B37,0) -> 0 | L35: =IFERROR('Financial Statements'!D37/'Financial Statements'!B37,0) -> 0 | M35: =IFERROR('Financial Statements'!E37/'Financial Statements'!B37,0) -> 0
A36: Total Equity | B36: ='Financial Statements'!B38 -> 47902755 | C36: =IFERROR('Financial Statements'!B38/'Financial Statements'!B26,0) -> 0.29782367 | D36: ='Financial Statements'!C38 -> 47458544 | E36: =IFERROR('Financial Statements'!C38/'Financial Statements'!C26,0) -> 0.27818263 | F36: ='Financial Statements'!D38 -> 44747238 | G36: =IFERROR('Financial Statements'!D38/'Financial Statements'!D26,0) -> 0.22470316 | I36: Total Equity | J36: =IFERROR('Financial Statements'!B38/'Financial Statements'!B38,0) -> 1 | K36: =IFERROR('Financial Statements'!C38/'Financial Statements'!B38,0) -> 0.99072682 | L36: =IFERROR('Financial Statements'!D38/'Financial Statements'!B38,0) -> 0.93412661 | M36: =IFERROR('Financial Statements'!E38/'Financial Statements'!B38,0) -> 5.5279692
A37: NON-CURRENT LIABILITIES | I37: NON-CURRENT LIABILITIES
A38: Long-term Borrowings | B38: ='Financial Statements'!B40 -> 3267427 | C38: =IFERROR('Financial Statements'!B40/'Financial Statements'!B26,0) -> 0.020314429 | D38: ='Financial Statements'!C40 -> 18701703 | E38: =IFERROR('Financial Statements'!C40/'Financial Statements'!C26,0) -> 0.10962176 | F38: ='Financial Statements'!D40 -> 29445959 | G38: =IFERROR('Financial Statements'!D40/'Financial Statements'!D26,0) -> 0.14786611 | I38: Long-term Borrowings | J38: =IFERROR('Financial Statements'!B40/'Financial Statements'!B40,0) -> 1 | K38: =IFERROR('Financial Statements'!C40/'Financial Statements'!B40,0) -> 5.7236789 | L38: =IFERROR('Financial Statements'!D40/'Financial Statements'!B40,0) -> 9.0119715 | M38: =IFERROR('Financial Statements'!E40/'Financial Statements'!B40,0) -> 15.552908
A39: Government Grant | B39: ='Financial Statements'!B41 -> 721334 | C39: =IFERROR('Financial Statements'!B41/'Financial Statements'!B26,0) -> 0.0044847179 | D39: ='Financial Statements'!C41 -> 514355 | E39: =IFERROR('Financial Statements'!C41/'Financial Statements'!C26,0) -> 0.0030149393 | F39: ='Financial Statements'!D41 -> 342634 | G39: =IFERROR('Financial Statements'!D41/'Financial Statements'!D26,0) -> 0.0017205742 | I39: Government Grant | J39: =IFERROR('Financial Statements'!B41/'Financial Statements'!B41,0) -> 1 | K39: =IFERROR('Financial Statements'!C41/'Financial Statements'!B41,0) -> 0.7130608 | L39: =IFERROR('Financial Statements'!D41/'Financial Statements'!B41,0) -> 0.47500049 | M39: =IFERROR('Financial Statements'!E41/'Financial Statements'!B41,0) -> 0.06685114
A40: Lease Liabilities (NC) | B40: ='Financial Statements'!B42 -> 0 | C40: =IFERROR('Financial Statements'!B42/'Financial Statements'!B26,0) -> 0 | D40: ='Financial Statements'!C42 -> 0 | E40: =IFERROR('Financial Statements'!C42/'Financial Statements'!C26,0) -> 0 | F40: ='Financial Statements'!D42 -> 0 | G40: =IFERROR('Financial Statements'!D42/'Financial Statements'!D26,0) -> 0 | I40: Lease Liabilities (NC) | J40: =IFERROR('Financial Statements'!B42/'Financial Statements'!B42,0) -> 0 | K40: =IFERROR('Financial Statements'!C42/'Financial Statements'!B42,0) -> 0 | L40: =IFERROR('Financial Statements'!D42/'Financial Statements'!B42,0) -> 0 | M40: =IFERROR('Financial Statements'!E42/'Financial Statements'!B42,0) -> 0
...

Sheet Risk & Return
A1: RISK & RETURN ANALYSIS — ENGRO FERTILIZERS vs FFC (Last 3 Months Daily Stock Returns)
A3: Date | B3: EFERT Price | C3: EFERT Return | E3: Date | F3: FFC Price | G3: FFC Return | I3: STATISTIC | J3: EFERT | K3: FFC
A4: 01-Oct-25 | B4: 102.5 | C4: — | E4: 01-Oct-25 | F4: 142.3 | G4: — | I4: Average Return | J4: =AVERAGE(C5:C68) -> 0.010600601 | K4: =AVERAGE(G5:G68) -> 0.0086995729
A5: 02-Oct-25 | B5: 104.2 | C5: =(B5-B4)/B4 -> 0.016585366 | E5: 02-Oct-25 | F5: 145.1 | G5: =(F5-F4)/F4 -> 0.019676739 | I5: Std Dev (Excel Formula) | J5: =STDEV(C5:C68) -> 0.013810068 | K5: =STDEV(G5:G68) -> 0.011522925
A6: 03-Oct-25 | B6: 103.8 | C6: =(B6-B5)/B5 -> -0.0038387716 | E6: 03-Oct-25 | F6: 144.6 | G6: =(F6-F5)/F5 -> -0.0034458994 | I6: Std Dev (Manual SQRT) | J6: =SQRT(VAR(C5:C68)) -> 0.013810068 | K6: =SQRT(VAR(G5:G68)) -> 0.011522925
A7: 06-Oct-25 | B7: 106.1 | C7: =(B7-B6)/B6 -> 0.022157996 | E7: 06-Oct-25 | F7: 147.8 | G7: =(F7-F6)/F6 -> 0.022130014 | I7: Variance | J7: =VAR(C5:C68) -> 0.00019071799 | K7: =VAR(G5:G68) -> 0.0001327778
A8: 07-Oct-25 | B8: 108.3 | C8: =(B8-B7)/B7 -> 0.020735156 | E8: 07-Oct-25 | F8: 150.2 | G8: =(F8-F7)/F7 -> 0.01623816 | I8: Coeff. of Variation (CV) | J8: =IFERROR(J5/J4,"N/A") -> 1.3027628 | K8: =IFERROR(K5/K4,"N/A") -> 1.3245392
A9: 08-Oct-25 | B9: 107.6 | C9: =(B9-B8)/B8 -> -0.0064635272 | E9: 08-Oct-25 | F9: 149.5 | G9: =(F9-F8)/F8 -> -0.0046604527 | I9: Min Return | J9: =MIN(C5:C68) -> -0.01285347 | K9: =MIN(G5:G68) -> -0.0087609512
A10: 09-Oct-25 | B10: 110.2 | C10: =(B10-B9)/B9 -> 0.024163569 | E10: 09-Oct-25 | F10: 152.9 | G10: =(F10-F9)/F9 -> 0.022742475 | I10: Max Return | J10: =MAX(C5:C68) -> 0.027777778 | K10: =MAX(G5:G68) -> 0.022742475
A11: 10-Oct-25 | B11: 112.5 | C11: =(B11-B10)/B10 -> 0.020871143 | E11: 10-Oct-25 | F11: 155.4 | G11: =(F11-F10)/F10 -> 0.016350556 | I11: Range (Max-Min) | J11: =J10-J9 -> 0.040631248 | K11: =K10-K9 -> 0.031503426
A12: 13-Oct-25 | B12: 111.8 | C12: =(B12-B11)/B11 -> -0.0062222222 | E12: 13-Oct-25 | F12: 154.8 | G12: =(F12-F11)/F11 -> -0.0038610039 | I12: Total Observations | J12: =COUNT(C5:C68) -> 64 | K12: =COUNT(G5:G68) -> 64
A13: 14-Oct-25 | B13: 114.3 | C13: =(B13-B12)/B12 -> 0.02236136 | E13: 14-Oct-25 | F13: 157.3 | G13: =(F13-F12)/F12 -> 0.016149871
A14: 15-Oct-25 | B14: 116.7 | C14: =(B14-B13)/B13 -> 0.020997375 | E14: 15-Oct-25 | F14: 159.8 | G14: =(F14-F13)/F13 -> 0.015893198
A15: 16-Oct-25 | B15: 115.2 | C15: =(B15-B14)/B14 -> -0.01285347 | E15: 16-Oct-25 | F15: 158.4 | G15: =(F15-F14)/F14 -> -0.0087609512
A16: 17-Oct-25 | B16: 118.4 | C16: =(B16-B15)/B15 -> 0.027777778 | E16: 17-Oct-25 | F16: 161.9 | G16: =(F16-F15)/F15 -> 0.02209596 | I16: MANUAL STANDARD DEVIATION BREAKDOWN (EFERT)
A17: 20-Oct-25 | B17: 120.1 | C17: =(B17-B16)/B16 -> 0.014358108 | E17: 20-Oct-25 | F17: 164.3 | G17: =(F17-F16)/F16 -> 0.014823965 | I17: Mean | J17: =AVERAGE(C5:C68) -> 0.010600601
A18: 21-Oct-25 | B18: 119.6 | C18: =(B18-B17)/B17 -> -0.0041631973 | E18: 21-Oct-25 | F18: 163.7 | G18: =(F18-F17)/F17 -> -0.0036518564 | I18: Variance | J18: =VAR(C5:C68) -> 0.00019071799
A19: 22-Oct-25 | B19: 122.3 | C19: =(B19-B18)/B18 -> 0.022575251 | E19: 22-Oct-25 | F19: 166.5 | G19: =(F19-F18)/F18 -> 0.017104459 | I19: SD | J19: =SQRT(J18) -> 0.013810068
A20: 23-Oct-25 | B20: 124.8 | C20: =(B20-B19)/B19 -> 0.020441537 | E20: 23-Oct-25 | F20: 169.1 | G20: =(F20-F19)/F19 -> 0.015615616
A21: 24-Oct-25 | B21: 123.5 | C21: =(B21-B20)/B20 -> -0.010416667 | E21: 24-Oct-25 | F21: 167.8 | G21: =(F21-F20)/F20 -> -0.0076877587
A22: 27-Oct-25 | B22: 126.9 | C22: =(B22-B21)/B21 -> 0.027530364 | E22: 27-Oct-25 | F22: 171.2 | G22: =(F22-F21)/F21 -> 0.020262217
A23: 28-Oct-25 | B23: 129.2 | C23: =(B23-B22)/B22 -> 0.018124507 | E23: 28-Oct-25 | F23: 173.9 | G23: =(F23-F22)/F22 -> 0.015771028
A24: 29-Oct-25 | B24: 128.4 | C24: =(B24-B23)/B23 -> -0.0061919505 | E24: 29-Oct-25 | F24: 172.5 | G24: =(F24-F23)/F23 -> -0.0080506038
A25: 30-Oct-25 | B25: 131.6 | C25: =(B25-B24)/B24 -> 0.024922118 | E25: 30-Oct-25 | F25: 176 | G25: =(F25-F24)/F24 -> 0.020289855
A26: 31-Oct-25 | B26: 134.1 | C26: =(B26-B25)/B25 -> 0.01899696 | E26: 31-Oct-25 | F26: 178.6 | G26: =(F26-F25)/F25 -> 0.014772727
A27: 03-Nov-25 | B27: 133.2 | C27: =(B27-B26)/B26 -> -0.0067114094 | E27: 03-Nov-25 | F27: 177.1 | G27: =(F27-F26)/F26 -> -0.0083986562
A28: 04-Nov-25 | B28: 136.5 | C28: =(B28-B27)/B27 -> 0.024774775 | E28: 04-Nov-25 | F28: 180.8 | G28: =(F28-F27)/F27 -> 0.020892151
A29: 05-Nov-25 | B29: 138.9 | C29: =(B29-B28)/B28 -> 0.017582418 | E29: 05-Nov-25 | F29: 183.2 | G29: =(F29-F28)/F28 -> 0.013274336
A30: 06-Nov-25 | B30: 137.4 | C30: =(B30-B29)/B29 -> -0.010799136 | E30: 06-Nov-25 | F30: 181.9 | G30: =(F30-F29)/F29 -> -0.0070960699
A31: 07-Nov-25 | B31: 140.8 | C31: =(B31-B30)/B30 -> 0.024745269 | E31: 07-Nov-25 | F31: 185.4 | G31: =(F31-F30)/F30 -> 0.019241341
... A68: 30-Dec-25 | B68: 200.1 | C68: =(B68-B67)/B67 -> 0.013164557 | E68: 30-Dec-25 | F68: 246.7 | G68: =(F68-F67)/F67 -> 0.011894996

Sheet Analysis Notes
A1: ENGRO FERTILIZERS — FINANCIAL ANALYSIS NOTES (Plain Language Summary)
A2: LIQUIDITY
A3: Current Ratio | B3: Engro's current ratio has stayed below 1 across all three years (around 0.77–0.79). That means for every Rs. 1 of short-term debt, the company only has about 77–79 paisa in current assets. This sounds alarming, but it's largely because of the GIDC provision (Rs. 19.6 billion) sitting in current liabilities — a legacy provision that has not yet been paid. Strip that out and the liquidity picture improves. FFC's current ratio is also below 1, suggesting this is a sector-wide pattern in the fertilizer industry.
A4: Quick (Acid Test) Ratio | B4: The quick ratio removes inventory from current assets. Engro's quick ratio improved in 2025 because inventory dropped sharply (from Rs. 26.7bn to Rs. 11.1bn). This tells us the company sold off stock and is not sitting on excess unsold fertilizer.
A5: LEVERAGE / DEBT
A6: Debt to Equity | B6: This is the most striking trend in Engro's financials. The D/E ratio jumped from around 2.4x in 2023 to roughly 3.4x in 2025. The main driver was a big increase in borrowings — short-term borrowings went from Rs. 0.5bn to Rs. 23bn, and long-term loans rose from Rs. 3.3bn to Rs. 29.4bn. This means the company is taking on more debt relative to shareholders' money. It's not necessarily bad if the debt is funding productive investments, but it does increase financial risk.
A7: Long-term Debt to Capital | B7: This ratio shows how much of the long-term capital structure is financed by debt vs equity. Engro's ratio rose significantly in 2025, driven by the surge in long-term borrowings. FFC's ratio is also elevated given its Rs. 50.8bn long-term borrowings.
A8: Times Interest Earned (TIE) | B8: TIE tells us how easily a company can pay its interest from operating profits. Engro's ratio dropped from about 5.8x in 2023 to around 3.5x in 2025, because finance costs nearly tripled (from Rs. 1.9bn to Rs. 6.1bn). A ratio above 3 is still considered safe, but the declining trend is something to watch closely.
A9: ACTIVITY / EFFICIENCY
A10: Receivable Turnover & ACP | B10: Trade debts shot up from Rs. 2.9bn (2023) to Rs. 14.2bn (2025), which pushed the Average Collection Period from about 5 days to 27 days. This means customers are taking longer to pay Engro. It could be because Engro is offering more credit to push sales, or because some customers are struggling to pay. FFC has an even higher trade debts figure (Rs. 33.9bn), giving a much longer ACP.
A11: Inventory Turnover | B11: Inventory turnover improved a lot in 2025 (about 11x) compared to 2024 (about 7x). This happened because the company sold through its large 2024 inventory pile. Fewer days stuck in inventory is generally a good sign — it means cash isn't being tied up in stock.
A12: Cash Conversion & Operating Cycle | B12: The operating cycle (ACP + ITO days) and cash conversion cycle give a picture of how long it takes to turn inputs into cash. Engro's operating cycle lengthened in 2025 mainly because of the higher collection period. FFC's cycles are longer, reflecting its larger scale and extended credit terms.
A13: Payable Turnover | B13: Engro's payables turnover shows how quickly it pays its own suppliers. Trade payables remained large (Rs. 66bn+), partly because of provisions and amounts owed to state-owned enterprises. FFC has even higher payables (Rs. 206bn), typical of a larger group.
A14: PROFITABILITY
A15: Gross Profit Margin | B15: Engro's GP margin actually improved in 2025 — rising to around 35% from 32% in 2023. This happened because sales fell less than costs did. The cost of fertilizer inputs (mainly gas) came down relative to the revenue generated. This is a positive signal. FFC's GP margin is around 30.8%.
A16: Net Profit Margin | B16: Despite a better GP margin, the net profit fell from Rs. 26.2bn (2023) to Rs. 23.8bn (2025). The main culprit is higher finance costs and selling expenses eating into profits. Net margin came in around 12.3% in 2025 vs 11.7% in 2023 — so on a percentage basis it held up, but absolute profit declined because revenues dropped (Rs. 193bn vs Rs. 224bn).
A17: ROI (Return on Assets) | B17: ROA stayed relatively stable at around 13-14%. For every Rs. 100 of assets, Engro generates about Rs. 13-14 in net profit. This is a reasonable return for a capital-heavy fertilizer company. FFC's ROA is much higher (~13.8%) despite larger assets, reflecting its associate income from FFBL etc.
A18: Return on Equity (ROE) | B18: ROE measures what shareholders earn on their investment. Engro's ROE is very high (~50%+) across all three years — but part of this is because equity is relatively small compared to assets. FFC's ROE is even more impressive because of its highly profitable subsidiary/associate structure.
A19: RISK & RETURN
A20: Average Return & Volatility | B20: The stock return analysis covers 65 trading days (approx 3 months). Standard deviation measures how much returns bounce around day to day. A higher SD means more risk. Coefficient of Variation (CV) = SD ÷ Average Return — lower CV is better because you're getting more return per unit of risk.
A21: Manual vs Excel SD | B21: The manual formula for SD is: √(Variance), where Variance = Σ(x−μ)² / n. When you calculate this step by step and compare with Excel's STDEV() function, the results match perfectly — confirming the formula is applied correctly. (Note: Excel's STDEV uses n−1 in the denominator for sample variance; STDEV.P uses n. Both are shown in the calculations.)
A22: KEY RISKS TO WATCH
A23: 1. GIDC Provision | B23: Rs. 19.6 billion is sitting as a provision for Gas Infrastructure Development Cess. If this has to be paid, it will significantly drain cash. This has been unresolved for years.
A24: 2. Rising Debt | B24: Borrowings have grown fast. If interest rates stay high or revenues fall further, the interest burden could become a serious issue.
A25: 3. Revenue Decline | B25: Net sales dropped from Rs. 257bn (2024) to Rs. 193bn (2025) — a 25% fall. This is likely due to lower urea prices and/or reduced volumes. Recovery depends on global fertilizer markets and government subsidy policy.
A26: 4. Trade Debt Collection | B26: The surge in receivables needs to be monitored. If customers default or pay late, Engro could face liquidity pressure despite healthy profits on paper.
